<?xml version="1.0"?>

<robot name="zizo" >

  <material name="black">
    <color rgba="0 0 0 1"/>
  </material>

  <material name="white">
    <color rgba="1 1 1 1"/>
  </material>

  <link name="base_link">
    <visual>
      <origin rpy="0 0 0" xyz="0 0 0.25" />
      <geometry>
      	<cylinder length="0.5" radius="0.1"/>
        <!-- <box size="0.2 0.2 0.5"/> -->
      </geometry>
      <material name="black"/>
    </visual>
  </link>

  <joint name="j0" type="continuous">
  	<axis xyz="0 0 1" />
    <parent link="base_link"/>
    <child link="l1"/>
    <origin xyz="0 0 0.5"/>
  </joint>

  <link name="l1">
    <visual>
      <origin rpy="0 0 0" xyz="0 0.15 0.05" />
      <geometry>
        <box size="0.2 0.5 0.1"/>
      </geometry>
      <material name="white"/>
    </visual>
  </link>

  <joint name="j1" type="revolute">
  	<axis xyz="0 0 1" />
  	<limit effort="0" velocity="0" lower="-2.35619" upper="2.35619" />
    <parent link="l1"/>
    <child link="l2"/>
    <origin xyz="0 0.35 0.1"/>
  </joint>

  <link name="l2">
    <visual>
      <origin rpy="0 0 0" xyz="0 0.15 0.025" />
      <geometry>
        <box size="0.2 0.5 0.05"/>
      </geometry>
      <material name="white"/>
    </visual>
  </link>

  <joint name="j2" type="prismatic">
  	<axis xyz="0 0 1" />
  	<limit effort="0" velocity="0" lower="-0.1" upper="0.1" />
    <parent link="l2"/>
    <child link="l3"/>
    <origin xyz="0 0.25 0.025"/>
  </joint>

  <link name="l3">
    <visual>
      <origin rpy="0 0 0" xyz="0 0 0" />
      <geometry>
      	<cylinder length="0.4" radius="0.025"/>
      </geometry>
      <material name="black"/>
    </visual>
  </link>

</robot>